<?xml version="1.0" encoding="utf-8"?>
<!-- This URDF was automatically created by SolidWorks to URDF Exporter! Originally created by Stephen Brawner (brawner@gmail.com) 
     Commit Version: 1.6.0-4-g7f85cfe  Build Version: 1.6.7995.38578
     For more information, please see http://wiki.ros.org/sw_urdf_exporter -->
<robot
  name="scara_description">
  <link
    name="base_link">
    <inertial>
      <origin
        xyz="0.0057621 0.0028578 0.19319"
        rpy="0 0 0" />
      <mass
        value="0.57218" />
      <inertia
        ixx="0.012428"
        ixy="4.9613E-05"
        ixz="-0.00072408"
        iyy="0.013027"
        iyz="0.00025556"
        izz="0.00072827" />
    </inertial>
    <visual>
      <origin
        xyz="0 0 0"
        rpy="0 0 0" />
      <geometry>
        <mesh
          filename="package://scara_description/meshes/base_link.STL" />
      </geometry>
      <material
        name="">
        <color
          rgba="0.79216 0.81961 0.93333 1" />
      </material>
    </visual>
    <collision>
      <origin
        xyz="0 0 0"
        rpy="0 0 0" />
      <geometry>
        <mesh
          filename="package://scara_description/meshes/base_link.STL" />
      </geometry>
    </collision>
  </link>
  <link
    name="link1">
    <inertial>
      <origin
        xyz="0.013832 0.069555 0.12417"
        rpy="0 0 0" />
      <mass
        value="0.27253" />
      <inertia
        ixx="0.00057162"
        ixy="1.0817E-06"
        ixz="-1.4268E-06"
        iyy="0.00039856"
        iyz="-0.0001182"
        izz="0.00066763" />
    </inertial>
    <visual>
      <origin
        xyz="0 0 0"
        rpy="0 0 0" />
      <geometry>
        <mesh
          filename="package://scara_description/meshes/link1.STL" />
      </geometry>
      <material
        name="">
        <color
          rgba="0.79216 0.81961 0.93333 1" />
      </material>
    </visual>
    <collision>
      <origin
        xyz="0 0 0"
        rpy="0 0 0" />
      <geometry>
        <mesh
          filename="package://scara_description/meshes/link1.STL" />
      </geometry>
    </collision>
  </link>
  <joint
    name="joint1"
    type="prismatic">
    <origin
      xyz="0 0 0"
      rpy="0 0 0" />
    <parent
      link="base_link" />
    <child
      link="link1" />
    <axis
      xyz="0 0 -1" />
    <limit
      lower="0"
      upper="252.45"
      effort="200"
      velocity="3" />
  </joint>
  <link
    name="link2">
    <inertial>
      <origin
        xyz="0.16522 0.0935 0.17078"
        rpy="0 0 0" />
      <mass
        value="0.58092" />
      <inertia
        ixx="0.00032773"
        ixy="-1.8277E-19"
        ixz="0.00014693"
        iyy="0.0043698"
        iyz="2.6585E-19"
        izz="0.0045086" />
    </inertial>
    <visual>
      <origin
        xyz="0 0 0"
        rpy="0 0 0" />
      <geometry>
        <mesh
          filename="package://scara_description/meshes/link2.STL" />
      </geometry>
      <material
        name="">
        <color
          rgba="0.79216 0.81961 0.93333 1" />
      </material>
    </visual>
    <collision>
      <origin
        xyz="0 0 0"
        rpy="0 0 0" />
      <geometry>
        <mesh
          filename="package://scara_description/meshes/link2.STL" />
      </geometry>
    </collision>
  </link>
  <joint
    name="joint2"
    type="revolute">
    <origin
      xyz="0 0 0"
      rpy="0 0 0" />
    <parent
      link="link1" />
    <child
      link="link2" />
    <axis
      xyz="0 0 1" />
    <limit
      lower="-0.7854"
      upper="1.7977"
      effort="200"
      velocity="3" />
  </joint>
  <link
    name="link3">
    <inertial>
      <origin
        xyz="0.34957 0.0935 0.22405"
        rpy="0 0 0" />
      <mass
        value="0.30095" />
      <inertia
        ixx="0.00016611"
        ixy="-5.3474E-19"
        ixz="-0.00017474"
        iyy="0.0030927"
        iyz="-1.7139E-19"
        izz="0.0030234" />
    </inertial>
    <visual>
      <origin
        xyz="0 0 0"
        rpy="0 0 0" />
      <geometry>
        <mesh
          filename="package://scara_description/meshes/link3.STL" />
      </geometry>
      <material
        name="">
        <color
          rgba="0.79216 0.81961 0.93333 1" />
      </material>
    </visual>
    <collision>
      <origin
        xyz="0 0 0"
        rpy="0 0 0" />
      <geometry>
        <mesh
          filename="package://scara_description/meshes/link3.STL" />
      </geometry>
    </collision>
  </link>
  <joint
    name="joint3"
    type="revolute">
    <origin
      xyz="0 0 0"
      rpy="0 0 0" />
    <parent
      link="link2" />
    <child
      link="link3" />
    <axis
      xyz="0 0 1" />
    <limit
      lower="-1.34390352"
      upper="4.01425728"
      effort="200"
      velocity="3" />
  </joint>
  <link
    name="link4">
    <inertial>
      <origin
        xyz="0.51309 0.16092 0.29357"
        rpy="0 0 0" />
      <mass
        value="0.16132" />
      <inertia
        ixx="0.00040057"
        ixy="-4.1022E-06"
        ixz="-4.7582E-06"
        iyy="0.00025268"
        iyz="-0.00014299"
        izz="0.00019938" />
    </inertial>
    <visual>
      <origin
        xyz="0 0 0"
        rpy="0 0 0" />
      <geometry>
        <mesh
          filename="package://scara_description/meshes/link4.STL" />
      </geometry>
      <material
        name="">
        <color
          rgba="0.79216 0.81961 0.93333 1" />
      </material>
    </visual>
    <collision>
      <origin
        xyz="0 0 0"
        rpy="0 0 0" />
      <geometry>
        <mesh
          filename="package://scara_description/meshes/link4.STL" />
      </geometry>
    </collision>
  </link>
  <joint
    name="joint4"
    type="revolute">
    <origin
      xyz="0 0 0"
      rpy="0 0 0" />
    <parent
      link="link3" />
    <child
      link="link4" />
    <axis
      xyz="0 0 1" />
    <limit
      lower="-2.6698"
      upper="3.0025"
      effort="200"
      velocity="3" />
  </joint>
  <link
    name="link5">
    <inertial>
      <origin
        xyz="0.50794 0.10102 0.31748"
        rpy="0 0 0" />
      <mass
        value="0.15899" />
      <inertia
        ixx="9.2458E-05"
        ixy="-7.9696E-07"
        ixz="-1.5446E-06"
        iyy="0.00011974"
        iyz="3.8986E-06"
        izz="0.00013471" />
    </inertial>
    <visual>
      <origin
        xyz="0 0 0"
        rpy="0 0 0" />
      <geometry>
        <mesh
          filename="package://scara_description/meshes/link5.STL" />
      </geometry>
      <material
        name="">
        <color
          rgba="0.79216 0.81961 0.93333 1" />
      </material>
    </visual>
    <collision>
      <origin
        xyz="0 0 0"
        rpy="0 0 0" />
      <geometry>
        <mesh
          filename="package://scara_description/meshes/link5.STL" />
      </geometry>
    </collision>
  </link>
  <joint
    name="joint5"
    type="revolute">
    <origin
      xyz="0 0 0"
      rpy="0 0 0" />
    <parent
      link="link4" />
    <child
      link="link5" />
    <axis
      xyz="0 1 0" />
    <limit
      lower="0"
      upper="0.69813"
      effort="200"
      velocity="3" />
  </joint>
  <link
    name="link6">
    <inertial>
      <origin
        xyz="0.58286 0.095012 0.31975"
        rpy="0 0 0" />
      <mass
        value="0.071797" />
      <inertia
        ixx="3.3372E-05"
        ixy="2.1998E-07"
        ixz="-4.6345E-06"
        iyy="4.7936E-05"
        iyz="7.7263E-07"
        izz="5.5607E-05" />
    </inertial>
    <visual>
      <origin
        xyz="0 0 0"
        rpy="0 0 0" />
      <geometry>
        <mesh
          filename="package://scara_description/meshes/link6.STL" />
      </geometry>
      <material
        name="">
        <color
          rgba="0.79216 0.81961 0.93333 1" />
      </material>
    </visual>
    <collision>
      <origin
        xyz="0 0 0"
        rpy="0 0 0" />
      <geometry>
        <mesh
          filename="package://scara_description/meshes/link6.STL" />
      </geometry>
    </collision>
  </link>
  <joint
    name="joint6"
    type="revolute">
    <origin
      xyz="0 0 0"
      rpy="0 0 0" />
    <parent
      link="link5" />
    <child
      link="link6" />
    <axis
      xyz="-1 0 0" />
    <limit
      lower="-3.1416"
      upper="0"
      effort="200"
      velocity="3" />
  </joint>
  <link
    name="link7">
    <inertial>
      <origin
        xyz="0.63538 0.0925 0.3162"
        rpy="0 0 0" />
      <mass
        value="0.065589" />
      <inertia
        ixx="2.3546E-05"
        ixy="3.3764E-22"
        ixz="-7.4239E-21"
        iyy="2.4477E-05"
        iyz="1.15E-20"
        izz="2.6169E-05" />
    </inertial>
    <visual>
      <origin
        xyz="0 0 0"
        rpy="0 0 0" />
      <geometry>
        <mesh
          filename="package://scara_description/meshes/link7.STL" />
      </geometry>
      <material
        name="">
        <color
          rgba="0.79216 0.81961 0.93333 1" />
      </material>
    </visual>
    <collision>
      <origin
        xyz="0 0 0"
        rpy="0 0 0" />
      <geometry>
        <mesh
          filename="package://scara_description/meshes/link7.STL" />
      </geometry>
    </collision>
  </link>
  <joint
    name="joint7"
    type="revolute">
    <origin
      xyz="0 0 0"
      rpy="0 0 0" />
    <parent
      link="link6" />
    <child
      link="link7" />
    <axis
      xyz="0 1 0" />
    <limit
      lower="-1.57079633"
      upper="0.17453293"
      effort="200"
      velocity="3" />
  </joint>
</robot>