<?xml version="1.0" encoding="utf-8"?>
<!-- This URDF was automatically created by SolidWorks to URDF Exporter! Originally created by Stephen Brawner (brawner@gmail.com) 
     Commit Version: 1.6.0-4-g7f85cfe  Build Version: 1.6.7995.38578
     For more information, please see http://wiki.ros.org/sw_urdf_exporter -->
<robot
  name="scara_description">
  <link
    name="base_link">
    <visual>
      <geometry>
        <mesh
          filename="package://scara_description/meshes/base_link.STL" />
      </geometry>
      <material
        name="mat">
        <color
          rgba="0.79216 0.81961 0.93333 1" />
      </material>
    </visual>
    <collision>
      <geometry>
        <mesh
          filename="package://scara_description/meshes/base_link.STL" />
      </geometry>
    </collision>
  </link>
  <link
    name="link1">
    <inertial>
      <origin
        xyz="0.013832 0.069555 0.12417"
        rpy="0.0 0.0 0.0" />
      <mass
        value="0.27253" />
      <inertia
        ixx="0.00057162"
        ixy="1.0817E-06"
        ixz="-1.4268E-06"
        iyy="0.00039856"
        iyz="-0.0001182"
        izz="0.00066763" />
    </inertial>
    <visual>
      <origin
        xyz="0.0 0.0 0.0"
        rpy="0.0 0.0 0.0" />
      <geometry>
        <mesh
          filename="package://scara_description/meshes/link1.STL" />
      </geometry>
      <material
        name="mat">
        <color
          rgba="0.79216 0.81961 0.93333 1" />
      </material>
    </visual>
    <collision>
      <origin
        xyz="0.0 0.0 0.0"
        rpy="0.0 0.0 0.0" />
      <geometry>
        <mesh
          filename="package://scara_description/meshes/link1.STL" />
      </geometry>
    </collision>
  </link>
  <joint
    name="joint1"
    type="prismatic">
    <origin
      xyz="0.0 0.0 0.0"
      rpy="0.0 0.0 0.0" />
    <parent
      link="base_link" />
    <child
      link="link1" />
    <axis
      xyz="0.0 0.0 -1" />
    <limit
      lower="-0.25245"
      upper="0"
      effort="200"
      velocity="3" />
  </joint>
  <link
    name="link2">
    <inertial>
      <origin
        xyz="0.15122 4.1633E-17 0.033583"
        rpy="0.0 0.0 0.0" />
      <mass
        value="0.58092" />
      <inertia
        ixx="0.00032773"
        ixy="-1.638E-19"
        ixz="0.00014693"
        iyy="0.0043698"
        iyz="2.5356E-19"
        izz="0.0045086" />
    </inertial>
    <visual>
      <origin
        xyz="0.0 0.0 0.0"
        rpy="0.0 0.0 0.0" />
      <geometry>
        <mesh
          filename="package://scara_description/meshes/link2.STL" />
      </geometry>
      <material
        name="mat">
        <color
          rgba="0.79216 0.81961 0.93333 1" />
      </material>
    </visual>
    <collision>
      <origin
        xyz="0.0 0.0 0.0"
        rpy="0.0 0.0 0.0" />
      <geometry>
        <mesh
          filename="package://scara_description/meshes/link2.STL" />
      </geometry>
    </collision>
  </link>
  <joint
    name="joint2"
    type="revolute">
    <origin
      xyz="0.014 0.0935 0.1372"
      rpy="0.0 0.0 0.0" />
    <parent
      link="link1" />
    <child
      link="link2" />
    <axis
      xyz="0.0 0.0 1.0" />
    <limit
      lower="-0.7854"
      upper="1.7977"
      effort="200"
      velocity="3" />
  </joint>
  <link
    name="link3">
    <inertial>
      <origin
        xyz="-1.3878E-17 0.12057 0.041448"
        rpy="0.0 0.0 0.0" />
      <mass
        value="0.30095" />
      <inertia
        ixx="0.0030927"
        ixy="-1.1397E-19"
        ixz="-2.8553E-20"
        iyy="0.00016611"
        iyz="-0.00017474"
        izz="0.0030234" />
    </inertial>
    <visual>
      <origin
        xyz="0.0 0.0 0.0"
        rpy="0.0 0.0 0.0" />
      <geometry>
        <mesh
          filename="package://scara_description/meshes/link3.STL" />
      </geometry>
      <material
        name="mat">
        <color
          rgba="0.79216 0.81961 0.93333 1" />
      </material>
    </visual>
    <collision>
      <origin
        xyz="0.0 0.0 0.0"
        rpy="0.0 0.0 0.0" />
      <geometry>
        <mesh
          filename="package://scara_description/meshes/link3.STL" />
      </geometry>
    </collision>
  </link>
  <joint
    name="joint3"
    type="revolute">
    <origin
      xyz="0.215 0 0.0454"
      rpy="0.0 0.0 -1.5708" />
    <parent
      link="link2" />
    <child
      link="link3" />
    <axis
      xyz="0.0 0.0 1.0" />
    <limit
      lower="-1.3439"
      upper="4.0143"
      effort="200"
      velocity="3" />
  </joint>
  <link
    name="link4">
    <inertial>
      <origin
        xyz="0.00091191 -0.067419 0.069367"
        rpy="0.0 0.0 0.0" />
      <mass
        value="0.16132" />
      <inertia
        ixx="0.00040057"
        ixy="-4.1022E-06"
        ixz="4.7582E-06"
        iyy="0.00025268"
        iyz="0.00014299"
        izz="0.00019938" />
    </inertial>
    <visual>
      <origin
        xyz="0.0 0.0 0.0"
        rpy="0.0 0.0 0.0" />
      <geometry>
        <mesh
          filename="package://scara_description/meshes/link4.STL" />
      </geometry>
      <material
        name="mat">
        <color
          rgba="0.79216 0.81961 0.93333 1" />
      </material>
    </visual>
    <collision>
      <origin
        xyz="0.0 0.0 0.0"
        rpy="0.0 0.0 0.0" />
      <geometry>
        <mesh
          filename="package://scara_description/meshes/link4.STL" />
      </geometry>
    </collision>
  </link>
  <joint
    name="joint4"
    type="revolute">
    <origin
      xyz="0 0.285 0.0416"
      rpy="0.0 0.0 -1.5708" />
    <parent
      link="link3" />
    <child
      link="link4" />
    <axis
      xyz="0.0 0.0 1.0" />
    <limit
      lower="-2.6698"
      upper="3.0025"
      effort="200"
      velocity="3" />
  </joint>
  <link
    name="link5">
    <inertial>
      <origin
        xyz="0.0060554 -0.0012752 0.039479"
        rpy="0.0 0.0 0.0" />
      <mass
        value="0.15899" />
      <inertia
        ixx="9.2458E-05"
        ixy="-1.5446E-06"
        ixz="-7.9696E-07"
        iyy="0.00013471"
        iyz="3.8986E-06"
        izz="0.00011974" />
    </inertial>
    <visual>
      <origin
        xyz="0.0 0.0 0.0"
        rpy="0.0 0.0 0.0" />
      <geometry>
        <mesh
          filename="package://scara_description/meshes/link5.STL" />
      </geometry>
      <material
        name="mat">
        <color
          rgba="0.79216 0.81961 0.93333 1" />
      </material>
    </visual>
    <collision>
      <origin
        xyz="0.0 0.0 0.0"
        rpy="0.0 0.0 0.0" />
      <geometry>
        <mesh
          filename="package://scara_description/meshes/link5.STL" />
      </geometry>
    </collision>
  </link>
  <joint
    name="joint5"
    type="revolute">
    <origin
      xyz="0 -0.047 0.092"
      rpy="-1.5708 0 0" />
    <parent
      link="link4" />
    <child
      link="link5" />
    <axis
      xyz="0.0 0.0 -1" />
    <limit
      lower="-0.69813"
      upper="0"
      effort="200"
      velocity="3" />
  </joint>
  <link
    name="link6">
    <inertial>
      <origin
        xyz="-0.003554 -0.0025118 -0.05101"
        rpy="0.0 0.0 0.0" />
      <mass
        value="0.071797" />
      <inertia
        ixx="5.5607E-05"
        ixy="7.7263E-07"
        ixz="-4.6345E-06"
        iyy="4.7936E-05"
        iyz="2.1998E-07"
        izz="3.3372E-05" />
    </inertial>
    <visual>
      <origin
        xyz="0.0 0.0 0.0"
        rpy="0.0 0.0 0.0" />
      <geometry>
        <mesh
          filename="package://scara_description/meshes/link6.STL" />
      </geometry>
      <material
        name="mat">
        <color
          rgba="0.79216 0.81961 0.93333 1" />
      </material>
    </visual>
    <collision>
      <origin
        xyz="0.0 0.0 0.0"
        rpy="0.0 0.0 0.0" />
      <geometry>
        <mesh
          filename="package://scara_description/meshes/link6.STL" />
      </geometry>
    </collision>
  </link>
  <joint
    name="joint6"
    type="revolute">
    <origin
      xyz="-0.01785 0 0.048"
      rpy="1.5708 0 1.5708" />
    <parent
      link="link5" />
    <child
      link="link6" />
    <axis
      xyz="0.0 0.0 1.0" />
    <limit
      lower="-3.1416"
      upper="0"
      effort="200"
      velocity="3" />
  </joint>
  <link
    name="link7">
    <inertial>
      <origin
        xyz="-0.011222 2.7756E-17 0"
        rpy="0.0 0.0 0.0" />
      <mass
        value="0.02813" />
      <inertia
        ixx="4.3683E-06"
        ixy="5.1544E-21"
        ixz="-1.9375E-23"
        iyy="6.5087E-06"
        iyz="1.1221E-20"
        izz="4.8166E-06" />
    </inertial>
    <visual>
      <origin
        xyz="0.0 0.0 0.0"
        rpy="0.0 0.0 0.0" />
      <geometry>
        <mesh
          filename="package://scara_description/meshes/link7.STL" />
      </geometry>
      <material
        name="mat">
        <color
          rgba="0.79216 0.81961 0.93333 1" />
      </material>
    </visual>
    <collision>
      <origin
        xyz="0.0 0.0 0.0"
        rpy="0.0 0.0 0.0" />
      <geometry>
        <mesh
          filename="package://scara_description/meshes/link7.STL" />
      </geometry>
    </collision>
  </link>
  <joint
    name="joint7"
    type="revolute">
    <origin
      xyz="0.0 0.0 -0.078405"
      rpy="1.5708 -1.5708 0" />
    <parent
      link="link6" />
    <child
      link="link7" />
    <axis
      xyz="0.0 0.0 1.0" />
    <limit
      lower="-1.5708"
      upper="0.17453"
      effort="200"
      velocity="3" />
  </joint>
  <link
    name="link8">
    <inertial>
      <origin
        xyz="-0.035573 2.7756E-17 8.3267E-17"
        rpy="0.0 0.0 0.0" />
      <mass
        value="0.037459" />
      <inertia
        ixx="1.9178E-05"
        ixy="-2.0171E-20"
        ixz="-1.017E-20"
        iyy="1.0134E-05"
        iyz="-1.5485E-21"
        izz="1.0134E-05" />
    </inertial>
    <visual>
      <origin
        xyz="0.0 0.0 0.0"
        rpy="0.0 0.0 0.0" />
      <geometry>
        <mesh
          filename="package://scara_description/meshes/link8.STL" />
      </geometry>
      <material
        name="mat">
        <color
          rgba="0.79216 0.81961 0.93333 1" />
      </material>
    </visual>
    <collision>
      <origin
        xyz="0.0 0.0 0.0"
        rpy="0.0 0.0 0.0" />
      <geometry>
        <mesh
          filename="package://scara_description/meshes/link8.STL" />
      </geometry>
    </collision>
  </link>
  <joint
    name="joint8"
    type="fixed">
    <origin
      xyz="0.0 0.0 0.0"
      rpy="0.0 0.0 0.0" />
    <parent
      link="link7" />
    <child
      link="link8" />
    <axis
      xyz="0.0 0.0 0.0" />
  </joint>
</robot>